INFO 2020-09-29 15:08:43,029 autoreload 30604 140566371305280 Watching for file changes with StatReloader
INFO 2020-09-29 15:13:43,024 autoreload 30741 139806888671040 Watching for file changes with StatReloader
INFO 2020-09-29 15:24:11,881 autoreload 31029 140039702284096 Watching for file changes with StatReloader
INFO 2020-09-29 15:24:32,605 autoreload 31045 140455980676928 Watching for file changes with StatReloader
ERROR 2020-09-30 12:45:44,701 log 30019 140181766911744 Internal Server Error: /api/check_resource/
Traceback (most recent call last):
  File "/home/cloudcopasi/cloud-copasi-new/ccEnv/lib64/python3.6/site-packages/django/core/handlers/exception.py", line 47, in inner
    response = get_response(request)
  File "/home/cloudcopasi/cloud-copasi-new/ccEnv/lib64/python3.6/site-packages/django/core/handlers/base.py", line 179, in _get_response
    response = wrapped_callback(request, *callback_args, **callback_kwargs)
  File "/home/cloudcopasi/cloud-copasi-new/ccEnv/lib64/python3.6/site-packages/django/views/generic/base.py", line 70, in view
    return self.dispatch(request, *args, **kwargs)
  File "/home/cloudcopasi/cloud-copasi-new/ccEnv/lib64/python3.6/site-packages/django/utils/decorators.py", line 43, in _wrapper
    return bound_method(*args, **kwargs)
  File "/home/cloudcopasi/cloud-copasi-new/ccEnv/lib64/python3.6/site-packages/django/views/decorators/csrf.py", line 54, in wrapped_view
    return view_func(*args, **kwargs)
  File "/home/cloudcopasi/cloud-copasi-new/cloud_copasi/web_interface/client_api/api_views.py", line 42, in dispatch
    return super(APIView, self).dispatch(request, *args, **kwargs)
  File "/home/cloudcopasi/cloud-copasi-new/ccEnv/lib64/python3.6/site-packages/django/views/generic/base.py", line 98, in dispatch
    return handler(request, *args, **kwargs)
  File "/home/cloudcopasi/cloud-copasi-new/cloud_copasi/web_interface/client_api/api_views.py", line 340, in get
    user_id = int(request.GET['user_id'])
ValueError: invalid literal for int() with base 10: 'None'
WARNING 2020-09-30 12:45:44,706 log 30019 140181800482560 Not Found: /favicon.ico
ERROR 2020-09-30 12:46:41,098 log 30019 140181800482560 Internal Server Error: /api/check_resource/
Traceback (most recent call last):
  File "/home/cloudcopasi/cloud-copasi-new/ccEnv/lib64/python3.6/site-packages/django/core/handlers/exception.py", line 47, in inner
    response = get_response(request)
  File "/home/cloudcopasi/cloud-copasi-new/ccEnv/lib64/python3.6/site-packages/django/core/handlers/base.py", line 179, in _get_response
    response = wrapped_callback(request, *callback_args, **callback_kwargs)
  File "/home/cloudcopasi/cloud-copasi-new/ccEnv/lib64/python3.6/site-packages/django/views/generic/base.py", line 70, in view
    return self.dispatch(request, *args, **kwargs)
  File "/home/cloudcopasi/cloud-copasi-new/ccEnv/lib64/python3.6/site-packages/django/utils/decorators.py", line 43, in _wrapper
    return bound_method(*args, **kwargs)
  File "/home/cloudcopasi/cloud-copasi-new/ccEnv/lib64/python3.6/site-packages/django/views/decorators/csrf.py", line 54, in wrapped_view
    return view_func(*args, **kwargs)
  File "/home/cloudcopasi/cloud-copasi-new/cloud_copasi/web_interface/client_api/api_views.py", line 42, in dispatch
    return super(APIView, self).dispatch(request, *args, **kwargs)
  File "/home/cloudcopasi/cloud-copasi-new/ccEnv/lib64/python3.6/site-packages/django/views/generic/base.py", line 98, in dispatch
    return handler(request, *args, **kwargs)
  File "/home/cloudcopasi/cloud-copasi-new/cloud_copasi/web_interface/client_api/api_views.py", line 340, in get
    user_id = int(request.GET['user_id'])
ValueError: invalid literal for int() with base 10: 'None'
ERROR 2020-09-30 12:46:43,813 log 30019 140181800482560 Internal Server Error: /api/check_resource/
Traceback (most recent call last):
  File "/home/cloudcopasi/cloud-copasi-new/ccEnv/lib64/python3.6/site-packages/django/core/handlers/exception.py", line 47, in inner
    response = get_response(request)
  File "/home/cloudcopasi/cloud-copasi-new/ccEnv/lib64/python3.6/site-packages/django/core/handlers/base.py", line 179, in _get_response
    response = wrapped_callback(request, *callback_args, **callback_kwargs)
  File "/home/cloudcopasi/cloud-copasi-new/ccEnv/lib64/python3.6/site-packages/django/views/generic/base.py", line 70, in view
    return self.dispatch(request, *args, **kwargs)
  File "/home/cloudcopasi/cloud-copasi-new/ccEnv/lib64/python3.6/site-packages/django/utils/decorators.py", line 43, in _wrapper
    return bound_method(*args, **kwargs)
  File "/home/cloudcopasi/cloud-copasi-new/ccEnv/lib64/python3.6/site-packages/django/views/decorators/csrf.py", line 54, in wrapped_view
    return view_func(*args, **kwargs)
  File "/home/cloudcopasi/cloud-copasi-new/cloud_copasi/web_interface/client_api/api_views.py", line 42, in dispatch
    return super(APIView, self).dispatch(request, *args, **kwargs)
  File "/home/cloudcopasi/cloud-copasi-new/ccEnv/lib64/python3.6/site-packages/django/views/generic/base.py", line 98, in dispatch
    return handler(request, *args, **kwargs)
  File "/home/cloudcopasi/cloud-copasi-new/cloud_copasi/web_interface/client_api/api_views.py", line 340, in get
    user_id = int(request.GET['user_id'])
ValueError: invalid literal for int() with base 10: 'None'
ERROR 2020-09-30 12:46:52,226 log 30019 140181800482560 Internal Server Error: /api/check_resource/
Traceback (most recent call last):
  File "/home/cloudcopasi/cloud-copasi-new/ccEnv/lib64/python3.6/site-packages/django/core/handlers/exception.py", line 47, in inner
    response = get_response(request)
  File "/home/cloudcopasi/cloud-copasi-new/ccEnv/lib64/python3.6/site-packages/django/core/handlers/base.py", line 179, in _get_response
    response = wrapped_callback(request, *callback_args, **callback_kwargs)
  File "/home/cloudcopasi/cloud-copasi-new/ccEnv/lib64/python3.6/site-packages/django/views/generic/base.py", line 70, in view
    return self.dispatch(request, *args, **kwargs)
  File "/home/cloudcopasi/cloud-copasi-new/ccEnv/lib64/python3.6/site-packages/django/utils/decorators.py", line 43, in _wrapper
    return bound_method(*args, **kwargs)
  File "/home/cloudcopasi/cloud-copasi-new/ccEnv/lib64/python3.6/site-packages/django/views/decorators/csrf.py", line 54, in wrapped_view
    return view_func(*args, **kwargs)
  File "/home/cloudcopasi/cloud-copasi-new/cloud_copasi/web_interface/client_api/api_views.py", line 42, in dispatch
    return super(APIView, self).dispatch(request, *args, **kwargs)
  File "/home/cloudcopasi/cloud-copasi-new/ccEnv/lib64/python3.6/site-packages/django/views/generic/base.py", line 98, in dispatch
    return handler(request, *args, **kwargs)
  File "/home/cloudcopasi/cloud-copasi-new/cloud_copasi/web_interface/client_api/api_views.py", line 340, in get
    user_id = int(request.GET['user_id'])
ValueError: invalid literal for int() with base 10: 'None'
ERROR 2020-09-30 12:46:54,288 log 30019 140181800482560 Internal Server Error: /api/check_resource/
Traceback (most recent call last):
  File "/home/cloudcopasi/cloud-copasi-new/ccEnv/lib64/python3.6/site-packages/django/core/handlers/exception.py", line 47, in inner
    response = get_response(request)
  File "/home/cloudcopasi/cloud-copasi-new/ccEnv/lib64/python3.6/site-packages/django/core/handlers/base.py", line 179, in _get_response
    response = wrapped_callback(request, *callback_args, **callback_kwargs)
  File "/home/cloudcopasi/cloud-copasi-new/ccEnv/lib64/python3.6/site-packages/django/views/generic/base.py", line 70, in view
    return self.dispatch(request, *args, **kwargs)
  File "/home/cloudcopasi/cloud-copasi-new/ccEnv/lib64/python3.6/site-packages/django/utils/decorators.py", line 43, in _wrapper
    return bound_method(*args, **kwargs)
  File "/home/cloudcopasi/cloud-copasi-new/ccEnv/lib64/python3.6/site-packages/django/views/decorators/csrf.py", line 54, in wrapped_view
    return view_func(*args, **kwargs)
  File "/home/cloudcopasi/cloud-copasi-new/cloud_copasi/web_interface/client_api/api_views.py", line 42, in dispatch
    return super(APIView, self).dispatch(request, *args, **kwargs)
  File "/home/cloudcopasi/cloud-copasi-new/ccEnv/lib64/python3.6/site-packages/django/views/generic/base.py", line 98, in dispatch
    return handler(request, *args, **kwargs)
  File "/home/cloudcopasi/cloud-copasi-new/cloud_copasi/web_interface/client_api/api_views.py", line 340, in get
    user_id = int(request.GET['user_id'])
ValueError: invalid literal for int() with base 10: 'None'
ERROR 2020-09-30 12:47:11,841 log 30019 140181800482560 Internal Server Error: /api/check_resource/
Traceback (most recent call last):
  File "/home/cloudcopasi/cloud-copasi-new/ccEnv/lib64/python3.6/site-packages/django/core/handlers/exception.py", line 47, in inner
    response = get_response(request)
  File "/home/cloudcopasi/cloud-copasi-new/ccEnv/lib64/python3.6/site-packages/django/core/handlers/base.py", line 179, in _get_response
    response = wrapped_callback(request, *callback_args, **callback_kwargs)
  File "/home/cloudcopasi/cloud-copasi-new/ccEnv/lib64/python3.6/site-packages/django/views/generic/base.py", line 70, in view
    return self.dispatch(request, *args, **kwargs)
  File "/home/cloudcopasi/cloud-copasi-new/ccEnv/lib64/python3.6/site-packages/django/utils/decorators.py", line 43, in _wrapper
    return bound_method(*args, **kwargs)
  File "/home/cloudcopasi/cloud-copasi-new/ccEnv/lib64/python3.6/site-packages/django/views/decorators/csrf.py", line 54, in wrapped_view
    return view_func(*args, **kwargs)
  File "/home/cloudcopasi/cloud-copasi-new/cloud_copasi/web_interface/client_api/api_views.py", line 42, in dispatch
    return super(APIView, self).dispatch(request, *args, **kwargs)
  File "/home/cloudcopasi/cloud-copasi-new/ccEnv/lib64/python3.6/site-packages/django/views/generic/base.py", line 98, in dispatch
    return handler(request, *args, **kwargs)
  File "/home/cloudcopasi/cloud-copasi-new/cloud_copasi/web_interface/client_api/api_views.py", line 340, in get
    user_id = int(request.GET['user_id'])
ValueError: invalid literal for int() with base 10: 'None'
ERROR 2020-09-30 12:47:13,466 log 30019 140181800482560 Internal Server Error: /api/check_resource/
Traceback (most recent call last):
  File "/home/cloudcopasi/cloud-copasi-new/ccEnv/lib64/python3.6/site-packages/django/core/handlers/exception.py", line 47, in inner
    response = get_response(request)
  File "/home/cloudcopasi/cloud-copasi-new/ccEnv/lib64/python3.6/site-packages/django/core/handlers/base.py", line 179, in _get_response
    response = wrapped_callback(request, *callback_args, **callback_kwargs)
  File "/home/cloudcopasi/cloud-copasi-new/ccEnv/lib64/python3.6/site-packages/django/views/generic/base.py", line 70, in view
    return self.dispatch(request, *args, **kwargs)
  File "/home/cloudcopasi/cloud-copasi-new/ccEnv/lib64/python3.6/site-packages/django/utils/decorators.py", line 43, in _wrapper
    return bound_method(*args, **kwargs)
  File "/home/cloudcopasi/cloud-copasi-new/ccEnv/lib64/python3.6/site-packages/django/views/decorators/csrf.py", line 54, in wrapped_view
    return view_func(*args, **kwargs)
  File "/home/cloudcopasi/cloud-copasi-new/cloud_copasi/web_interface/client_api/api_views.py", line 42, in dispatch
    return super(APIView, self).dispatch(request, *args, **kwargs)
  File "/home/cloudcopasi/cloud-copasi-new/ccEnv/lib64/python3.6/site-packages/django/views/generic/base.py", line 98, in dispatch
    return handler(request, *args, **kwargs)
  File "/home/cloudcopasi/cloud-copasi-new/cloud_copasi/web_interface/client_api/api_views.py", line 340, in get
    user_id = int(request.GET['user_id'])
ValueError: invalid literal for int() with base 10: 'None'
ERROR 2020-09-30 12:47:21,094 log 30019 140181800482560 Internal Server Error: /api/check_resource/
Traceback (most recent call last):
  File "/home/cloudcopasi/cloud-copasi-new/ccEnv/lib64/python3.6/site-packages/django/core/handlers/exception.py", line 47, in inner
    response = get_response(request)
  File "/home/cloudcopasi/cloud-copasi-new/ccEnv/lib64/python3.6/site-packages/django/core/handlers/base.py", line 179, in _get_response
    response = wrapped_callback(request, *callback_args, **callback_kwargs)
  File "/home/cloudcopasi/cloud-copasi-new/ccEnv/lib64/python3.6/site-packages/django/views/generic/base.py", line 70, in view
    return self.dispatch(request, *args, **kwargs)
  File "/home/cloudcopasi/cloud-copasi-new/ccEnv/lib64/python3.6/site-packages/django/utils/decorators.py", line 43, in _wrapper
    return bound_method(*args, **kwargs)
  File "/home/cloudcopasi/cloud-copasi-new/ccEnv/lib64/python3.6/site-packages/django/views/decorators/csrf.py", line 54, in wrapped_view
    return view_func(*args, **kwargs)
  File "/home/cloudcopasi/cloud-copasi-new/cloud_copasi/web_interface/client_api/api_views.py", line 42, in dispatch
    return super(APIView, self).dispatch(request, *args, **kwargs)
  File "/home/cloudcopasi/cloud-copasi-new/ccEnv/lib64/python3.6/site-packages/django/views/generic/base.py", line 98, in dispatch
    return handler(request, *args, **kwargs)
  File "/home/cloudcopasi/cloud-copasi-new/cloud_copasi/web_interface/client_api/api_views.py", line 340, in get
    user_id = int(request.GET['user_id'])
ValueError: invalid literal for int() with base 10: 'None'
ERROR 2020-09-30 12:47:28,868 log 30019 140181800482560 Internal Server Error: /api/check_resource/
Traceback (most recent call last):
  File "/home/cloudcopasi/cloud-copasi-new/ccEnv/lib64/python3.6/site-packages/django/core/handlers/exception.py", line 47, in inner
    response = get_response(request)
  File "/home/cloudcopasi/cloud-copasi-new/ccEnv/lib64/python3.6/site-packages/django/core/handlers/base.py", line 179, in _get_response
    response = wrapped_callback(request, *callback_args, **callback_kwargs)
  File "/home/cloudcopasi/cloud-copasi-new/ccEnv/lib64/python3.6/site-packages/django/views/generic/base.py", line 70, in view
    return self.dispatch(request, *args, **kwargs)
  File "/home/cloudcopasi/cloud-copasi-new/ccEnv/lib64/python3.6/site-packages/django/utils/decorators.py", line 43, in _wrapper
    return bound_method(*args, **kwargs)
  File "/home/cloudcopasi/cloud-copasi-new/ccEnv/lib64/python3.6/site-packages/django/views/decorators/csrf.py", line 54, in wrapped_view
    return view_func(*args, **kwargs)
  File "/home/cloudcopasi/cloud-copasi-new/cloud_copasi/web_interface/client_api/api_views.py", line 42, in dispatch
    return super(APIView, self).dispatch(request, *args, **kwargs)
  File "/home/cloudcopasi/cloud-copasi-new/ccEnv/lib64/python3.6/site-packages/django/views/generic/base.py", line 98, in dispatch
    return handler(request, *args, **kwargs)
  File "/home/cloudcopasi/cloud-copasi-new/cloud_copasi/web_interface/client_api/api_views.py", line 340, in get
    user_id = int(request.GET['user_id'])
ValueError: invalid literal for int() with base 10: 'None'
ERROR 2020-09-30 12:47:31,004 log 30019 140181800482560 Internal Server Error: /api/check_resource/
Traceback (most recent call last):
  File "/home/cloudcopasi/cloud-copasi-new/ccEnv/lib64/python3.6/site-packages/django/core/handlers/exception.py", line 47, in inner
    response = get_response(request)
  File "/home/cloudcopasi/cloud-copasi-new/ccEnv/lib64/python3.6/site-packages/django/core/handlers/base.py", line 179, in _get_response
    response = wrapped_callback(request, *callback_args, **callback_kwargs)
  File "/home/cloudcopasi/cloud-copasi-new/ccEnv/lib64/python3.6/site-packages/django/views/generic/base.py", line 70, in view
    return self.dispatch(request, *args, **kwargs)
  File "/home/cloudcopasi/cloud-copasi-new/ccEnv/lib64/python3.6/site-packages/django/utils/decorators.py", line 43, in _wrapper
    return bound_method(*args, **kwargs)
  File "/home/cloudcopasi/cloud-copasi-new/ccEnv/lib64/python3.6/site-packages/django/views/decorators/csrf.py", line 54, in wrapped_view
    return view_func(*args, **kwargs)
  File "/home/cloudcopasi/cloud-copasi-new/cloud_copasi/web_interface/client_api/api_views.py", line 42, in dispatch
    return super(APIView, self).dispatch(request, *args, **kwargs)
  File "/home/cloudcopasi/cloud-copasi-new/ccEnv/lib64/python3.6/site-packages/django/views/generic/base.py", line 98, in dispatch
    return handler(request, *args, **kwargs)
  File "/home/cloudcopasi/cloud-copasi-new/cloud_copasi/web_interface/client_api/api_views.py", line 340, in get
    user_id = int(request.GET['user_id'])
ValueError: invalid literal for int() with base 10: 'None'
ERROR 2020-09-30 12:47:32,872 log 30019 140181800482560 Internal Server Error: /api/check_resource/
Traceback (most recent call last):
  File "/home/cloudcopasi/cloud-copasi-new/ccEnv/lib64/python3.6/site-packages/django/core/handlers/exception.py", line 47, in inner
    response = get_response(request)
  File "/home/cloudcopasi/cloud-copasi-new/ccEnv/lib64/python3.6/site-packages/django/core/handlers/base.py", line 179, in _get_response
    response = wrapped_callback(request, *callback_args, **callback_kwargs)
  File "/home/cloudcopasi/cloud-copasi-new/ccEnv/lib64/python3.6/site-packages/django/views/generic/base.py", line 70, in view
    return self.dispatch(request, *args, **kwargs)
  File "/home/cloudcopasi/cloud-copasi-new/ccEnv/lib64/python3.6/site-packages/django/utils/decorators.py", line 43, in _wrapper
    return bound_method(*args, **kwargs)
  File "/home/cloudcopasi/cloud-copasi-new/ccEnv/lib64/python3.6/site-packages/django/views/decorators/csrf.py", line 54, in wrapped_view
    return view_func(*args, **kwargs)
  File "/home/cloudcopasi/cloud-copasi-new/cloud_copasi/web_interface/client_api/api_views.py", line 42, in dispatch
    return super(APIView, self).dispatch(request, *args, **kwargs)
  File "/home/cloudcopasi/cloud-copasi-new/ccEnv/lib64/python3.6/site-packages/django/views/generic/base.py", line 98, in dispatch
    return handler(request, *args, **kwargs)
  File "/home/cloudcopasi/cloud-copasi-new/cloud_copasi/web_interface/client_api/api_views.py", line 340, in get
    user_id = int(request.GET['user_id'])
ValueError: invalid literal for int() with base 10: 'None'
ERROR 2020-09-30 13:01:46,916 log 30019 140181800482560 Internal Server Error: /api/check_resource/
Traceback (most recent call last):
  File "/home/cloudcopasi/cloud-copasi-new/ccEnv/lib64/python3.6/site-packages/django/core/handlers/exception.py", line 47, in inner
    response = get_response(request)
  File "/home/cloudcopasi/cloud-copasi-new/ccEnv/lib64/python3.6/site-packages/django/core/handlers/base.py", line 179, in _get_response
    response = wrapped_callback(request, *callback_args, **callback_kwargs)
  File "/home/cloudcopasi/cloud-copasi-new/ccEnv/lib64/python3.6/site-packages/django/views/generic/base.py", line 70, in view
    return self.dispatch(request, *args, **kwargs)
  File "/home/cloudcopasi/cloud-copasi-new/ccEnv/lib64/python3.6/site-packages/django/utils/decorators.py", line 43, in _wrapper
    return bound_method(*args, **kwargs)
  File "/home/cloudcopasi/cloud-copasi-new/ccEnv/lib64/python3.6/site-packages/django/views/decorators/csrf.py", line 54, in wrapped_view
    return view_func(*args, **kwargs)
  File "/home/cloudcopasi/cloud-copasi-new/cloud_copasi/web_interface/client_api/api_views.py", line 42, in dispatch
    return super(APIView, self).dispatch(request, *args, **kwargs)
  File "/home/cloudcopasi/cloud-copasi-new/ccEnv/lib64/python3.6/site-packages/django/views/generic/base.py", line 98, in dispatch
    return handler(request, *args, **kwargs)
  File "/home/cloudcopasi/cloud-copasi-new/cloud_copasi/web_interface/client_api/api_views.py", line 340, in get
    user_id = int(request.GET['user_id'])
ValueError: invalid literal for int() with base 10: 'None'
ERROR 2020-09-30 13:01:53,957 log 30019 140181800482560 Internal Server Error: /api/check_resource/
Traceback (most recent call last):
  File "/home/cloudcopasi/cloud-copasi-new/ccEnv/lib64/python3.6/site-packages/django/core/handlers/exception.py", line 47, in inner
    response = get_response(request)
  File "/home/cloudcopasi/cloud-copasi-new/ccEnv/lib64/python3.6/site-packages/django/core/handlers/base.py", line 179, in _get_response
    response = wrapped_callback(request, *callback_args, **callback_kwargs)
  File "/home/cloudcopasi/cloud-copasi-new/ccEnv/lib64/python3.6/site-packages/django/views/generic/base.py", line 70, in view
    return self.dispatch(request, *args, **kwargs)
  File "/home/cloudcopasi/cloud-copasi-new/ccEnv/lib64/python3.6/site-packages/django/utils/decorators.py", line 43, in _wrapper
    return bound_method(*args, **kwargs)
  File "/home/cloudcopasi/cloud-copasi-new/ccEnv/lib64/python3.6/site-packages/django/views/decorators/csrf.py", line 54, in wrapped_view
    return view_func(*args, **kwargs)
  File "/home/cloudcopasi/cloud-copasi-new/cloud_copasi/web_interface/client_api/api_views.py", line 42, in dispatch
    return super(APIView, self).dispatch(request, *args, **kwargs)
  File "/home/cloudcopasi/cloud-copasi-new/ccEnv/lib64/python3.6/site-packages/django/views/generic/base.py", line 98, in dispatch
    return handler(request, *args, **kwargs)
  File "/home/cloudcopasi/cloud-copasi-new/cloud_copasi/web_interface/client_api/api_views.py", line 340, in get
    user_id = int(request.GET['user_id'])
ValueError: invalid literal for int() with base 10: 'None'
WARNING 2020-09-30 13:02:37,123 log 30019 140181766911744 Not Found: /api/spot_price/
ERROR 2020-09-30 13:02:37,133 log 30019 140181800482560 Internal Server Error: /api/check_resource/
Traceback (most recent call last):
  File "/home/cloudcopasi/cloud-copasi-new/ccEnv/lib64/python3.6/site-packages/django/core/handlers/exception.py", line 47, in inner
    response = get_response(request)
  File "/home/cloudcopasi/cloud-copasi-new/ccEnv/lib64/python3.6/site-packages/django/core/handlers/base.py", line 179, in _get_response
    response = wrapped_callback(request, *callback_args, **callback_kwargs)
  File "/home/cloudcopasi/cloud-copasi-new/ccEnv/lib64/python3.6/site-packages/django/views/generic/base.py", line 70, in view
    return self.dispatch(request, *args, **kwargs)
  File "/home/cloudcopasi/cloud-copasi-new/ccEnv/lib64/python3.6/site-packages/django/utils/decorators.py", line 43, in _wrapper
    return bound_method(*args, **kwargs)
  File "/home/cloudcopasi/cloud-copasi-new/ccEnv/lib64/python3.6/site-packages/django/views/decorators/csrf.py", line 54, in wrapped_view
    return view_func(*args, **kwargs)
  File "/home/cloudcopasi/cloud-copasi-new/cloud_copasi/web_interface/client_api/api_views.py", line 42, in dispatch
    return super(APIView, self).dispatch(request, *args, **kwargs)
  File "/home/cloudcopasi/cloud-copasi-new/ccEnv/lib64/python3.6/site-packages/django/views/generic/base.py", line 98, in dispatch
    return handler(request, *args, **kwargs)
  File "/home/cloudcopasi/cloud-copasi-new/cloud_copasi/web_interface/client_api/api_views.py", line 340, in get
    user_id = int(request.GET['user_id'])
ValueError: invalid literal for int() with base 10: 'None'
ERROR 2020-09-30 13:04:55,076 log 30019 140181800482560 Internal Server Error: /api/check_resource/
Traceback (most recent call last):
  File "/home/cloudcopasi/cloud-copasi-new/ccEnv/lib64/python3.6/site-packages/django/core/handlers/exception.py", line 47, in inner
    response = get_response(request)
  File "/home/cloudcopasi/cloud-copasi-new/ccEnv/lib64/python3.6/site-packages/django/core/handlers/base.py", line 179, in _get_response
    response = wrapped_callback(request, *callback_args, **callback_kwargs)
  File "/home/cloudcopasi/cloud-copasi-new/ccEnv/lib64/python3.6/site-packages/django/views/generic/base.py", line 70, in view
    return self.dispatch(request, *args, **kwargs)
  File "/home/cloudcopasi/cloud-copasi-new/ccEnv/lib64/python3.6/site-packages/django/utils/decorators.py", line 43, in _wrapper
    return bound_method(*args, **kwargs)
  File "/home/cloudcopasi/cloud-copasi-new/ccEnv/lib64/python3.6/site-packages/django/views/decorators/csrf.py", line 54, in wrapped_view
    return view_func(*args, **kwargs)
  File "/home/cloudcopasi/cloud-copasi-new/cloud_copasi/web_interface/client_api/api_views.py", line 42, in dispatch
    return super(APIView, self).dispatch(request, *args, **kwargs)
  File "/home/cloudcopasi/cloud-copasi-new/ccEnv/lib64/python3.6/site-packages/django/views/generic/base.py", line 98, in dispatch
    return handler(request, *args, **kwargs)
  File "/home/cloudcopasi/cloud-copasi-new/cloud_copasi/web_interface/client_api/api_views.py", line 340, in get
    user_id = int(request.GET['user_id'])
ValueError: invalid literal for int() with base 10: 'None'
ERROR 2020-09-30 13:04:56,018 log 30019 140181800482560 Internal Server Error: /api/check_resource/
Traceback (most recent call last):
  File "/home/cloudcopasi/cloud-copasi-new/ccEnv/lib64/python3.6/site-packages/django/core/handlers/exception.py", line 47, in inner
    response = get_response(request)
  File "/home/cloudcopasi/cloud-copasi-new/ccEnv/lib64/python3.6/site-packages/django/core/handlers/base.py", line 179, in _get_response
    response = wrapped_callback(request, *callback_args, **callback_kwargs)
  File "/home/cloudcopasi/cloud-copasi-new/ccEnv/lib64/python3.6/site-packages/django/views/generic/base.py", line 70, in view
    return self.dispatch(request, *args, **kwargs)
  File "/home/cloudcopasi/cloud-copasi-new/ccEnv/lib64/python3.6/site-packages/django/utils/decorators.py", line 43, in _wrapper
    return bound_method(*args, **kwargs)
  File "/home/cloudcopasi/cloud-copasi-new/ccEnv/lib64/python3.6/site-packages/django/views/decorators/csrf.py", line 54, in wrapped_view
    return view_func(*args, **kwargs)
  File "/home/cloudcopasi/cloud-copasi-new/cloud_copasi/web_interface/client_api/api_views.py", line 42, in dispatch
    return super(APIView, self).dispatch(request, *args, **kwargs)
  File "/home/cloudcopasi/cloud-copasi-new/ccEnv/lib64/python3.6/site-packages/django/views/generic/base.py", line 98, in dispatch
    return handler(request, *args, **kwargs)
  File "/home/cloudcopasi/cloud-copasi-new/cloud_copasi/web_interface/client_api/api_views.py", line 340, in get
    user_id = int(request.GET['user_id'])
ValueError: invalid literal for int() with base 10: 'None'
ERROR 2020-09-30 13:05:02,945 log 30019 140181800482560 Internal Server Error: /api/check_resource/
Traceback (most recent call last):
  File "/home/cloudcopasi/cloud-copasi-new/ccEnv/lib64/python3.6/site-packages/django/core/handlers/exception.py", line 47, in inner
    response = get_response(request)
  File "/home/cloudcopasi/cloud-copasi-new/ccEnv/lib64/python3.6/site-packages/django/core/handlers/base.py", line 179, in _get_response
    response = wrapped_callback(request, *callback_args, **callback_kwargs)
  File "/home/cloudcopasi/cloud-copasi-new/ccEnv/lib64/python3.6/site-packages/django/views/generic/base.py", line 70, in view
    return self.dispatch(request, *args, **kwargs)
  File "/home/cloudcopasi/cloud-copasi-new/ccEnv/lib64/python3.6/site-packages/django/utils/decorators.py", line 43, in _wrapper
    return bound_method(*args, **kwargs)
  File "/home/cloudcopasi/cloud-copasi-new/ccEnv/lib64/python3.6/site-packages/django/views/decorators/csrf.py", line 54, in wrapped_view
    return view_func(*args, **kwargs)
  File "/home/cloudcopasi/cloud-copasi-new/cloud_copasi/web_interface/client_api/api_views.py", line 42, in dispatch
    return super(APIView, self).dispatch(request, *args, **kwargs)
  File "/home/cloudcopasi/cloud-copasi-new/ccEnv/lib64/python3.6/site-packages/django/views/generic/base.py", line 98, in dispatch
    return handler(request, *args, **kwargs)
  File "/home/cloudcopasi/cloud-copasi-new/cloud_copasi/web_interface/client_api/api_views.py", line 340, in get
    user_id = int(request.GET['user_id'])
ValueError: invalid literal for int() with base 10: 'None'
ERROR 2020-09-30 13:05:09,048 log 30019 140181800482560 Internal Server Error: /api/check_resource/
Traceback (most recent call last):
  File "/home/cloudcopasi/cloud-copasi-new/ccEnv/lib64/python3.6/site-packages/django/core/handlers/exception.py", line 47, in inner
    response = get_response(request)
  File "/home/cloudcopasi/cloud-copasi-new/ccEnv/lib64/python3.6/site-packages/django/core/handlers/base.py", line 179, in _get_response
    response = wrapped_callback(request, *callback_args, **callback_kwargs)
  File "/home/cloudcopasi/cloud-copasi-new/ccEnv/lib64/python3.6/site-packages/django/views/generic/base.py", line 70, in view
    return self.dispatch(request, *args, **kwargs)
  File "/home/cloudcopasi/cloud-copasi-new/ccEnv/lib64/python3.6/site-packages/django/utils/decorators.py", line 43, in _wrapper
    return bound_method(*args, **kwargs)
  File "/home/cloudcopasi/cloud-copasi-new/ccEnv/lib64/python3.6/site-packages/django/views/decorators/csrf.py", line 54, in wrapped_view
    return view_func(*args, **kwargs)
  File "/home/cloudcopasi/cloud-copasi-new/cloud_copasi/web_interface/client_api/api_views.py", line 42, in dispatch
    return super(APIView, self).dispatch(request, *args, **kwargs)
  File "/home/cloudcopasi/cloud-copasi-new/ccEnv/lib64/python3.6/site-packages/django/views/generic/base.py", line 98, in dispatch
    return handler(request, *args, **kwargs)
  File "/home/cloudcopasi/cloud-copasi-new/cloud_copasi/web_interface/client_api/api_views.py", line 340, in get
    user_id = int(request.GET['user_id'])
ValueError: invalid literal for int() with base 10: 'None'
ERROR 2020-09-30 13:05:14,050 log 30019 140181800482560 Internal Server Error: /api/check_resource/
Traceback (most recent call last):
  File "/home/cloudcopasi/cloud-copasi-new/ccEnv/lib64/python3.6/site-packages/django/core/handlers/exception.py", line 47, in inner
    response = get_response(request)
  File "/home/cloudcopasi/cloud-copasi-new/ccEnv/lib64/python3.6/site-packages/django/core/handlers/base.py", line 179, in _get_response
    response = wrapped_callback(request, *callback_args, **callback_kwargs)
  File "/home/cloudcopasi/cloud-copasi-new/ccEnv/lib64/python3.6/site-packages/django/views/generic/base.py", line 70, in view
    return self.dispatch(request, *args, **kwargs)
  File "/home/cloudcopasi/cloud-copasi-new/ccEnv/lib64/python3.6/site-packages/django/utils/decorators.py", line 43, in _wrapper
    return bound_method(*args, **kwargs)
  File "/home/cloudcopasi/cloud-copasi-new/ccEnv/lib64/python3.6/site-packages/django/views/decorators/csrf.py", line 54, in wrapped_view
    return view_func(*args, **kwargs)
  File "/home/cloudcopasi/cloud-copasi-new/cloud_copasi/web_interface/client_api/api_views.py", line 42, in dispatch
    return super(APIView, self).dispatch(request, *args, **kwargs)
  File "/home/cloudcopasi/cloud-copasi-new/ccEnv/lib64/python3.6/site-packages/django/views/generic/base.py", line 98, in dispatch
    return handler(request, *args, **kwargs)
  File "/home/cloudcopasi/cloud-copasi-new/cloud_copasi/web_interface/client_api/api_views.py", line 340, in get
    user_id = int(request.GET['user_id'])
ValueError: invalid literal for int() with base 10: 'None'
ERROR 2020-09-30 13:07:29,104 log 30019 140181800482560 Internal Server Error: /api/check_resource/
Traceback (most recent call last):
  File "/home/cloudcopasi/cloud-copasi-new/ccEnv/lib64/python3.6/site-packages/django/core/handlers/exception.py", line 47, in inner
    response = get_response(request)
  File "/home/cloudcopasi/cloud-copasi-new/ccEnv/lib64/python3.6/site-packages/django/core/handlers/base.py", line 179, in _get_response
    response = wrapped_callback(request, *callback_args, **callback_kwargs)
  File "/home/cloudcopasi/cloud-copasi-new/ccEnv/lib64/python3.6/site-packages/django/views/generic/base.py", line 70, in view
    return self.dispatch(request, *args, **kwargs)
  File "/home/cloudcopasi/cloud-copasi-new/ccEnv/lib64/python3.6/site-packages/django/utils/decorators.py", line 43, in _wrapper
    return bound_method(*args, **kwargs)
  File "/home/cloudcopasi/cloud-copasi-new/ccEnv/lib64/python3.6/site-packages/django/views/decorators/csrf.py", line 54, in wrapped_view
    return view_func(*args, **kwargs)
  File "/home/cloudcopasi/cloud-copasi-new/cloud_copasi/web_interface/client_api/api_views.py", line 42, in dispatch
    return super(APIView, self).dispatch(request, *args, **kwargs)
  File "/home/cloudcopasi/cloud-copasi-new/ccEnv/lib64/python3.6/site-packages/django/views/generic/base.py", line 98, in dispatch
    return handler(request, *args, **kwargs)
  File "/home/cloudcopasi/cloud-copasi-new/cloud_copasi/web_interface/client_api/api_views.py", line 340, in get
    user_id = int(request.GET['user_id'])
ValueError: invalid literal for int() with base 10: 'None'
ERROR 2020-09-30 13:07:30,875 log 30019 140181800482560 Internal Server Error: /api/check_resource/
Traceback (most recent call last):
  File "/home/cloudcopasi/cloud-copasi-new/ccEnv/lib64/python3.6/site-packages/django/core/handlers/exception.py", line 47, in inner
    response = get_response(request)
  File "/home/cloudcopasi/cloud-copasi-new/ccEnv/lib64/python3.6/site-packages/django/core/handlers/base.py", line 179, in _get_response
    response = wrapped_callback(request, *callback_args, **callback_kwargs)
  File "/home/cloudcopasi/cloud-copasi-new/ccEnv/lib64/python3.6/site-packages/django/views/generic/base.py", line 70, in view
    return self.dispatch(request, *args, **kwargs)
  File "/home/cloudcopasi/cloud-copasi-new/ccEnv/lib64/python3.6/site-packages/django/utils/decorators.py", line 43, in _wrapper
    return bound_method(*args, **kwargs)
  File "/home/cloudcopasi/cloud-copasi-new/ccEnv/lib64/python3.6/site-packages/django/views/decorators/csrf.py", line 54, in wrapped_view
    return view_func(*args, **kwargs)
  File "/home/cloudcopasi/cloud-copasi-new/cloud_copasi/web_interface/client_api/api_views.py", line 42, in dispatch
    return super(APIView, self).dispatch(request, *args, **kwargs)
  File "/home/cloudcopasi/cloud-copasi-new/ccEnv/lib64/python3.6/site-packages/django/views/generic/base.py", line 98, in dispatch
    return handler(request, *args, **kwargs)
  File "/home/cloudcopasi/cloud-copasi-new/cloud_copasi/web_interface/client_api/api_views.py", line 340, in get
    user_id = int(request.GET['user_id'])
ValueError: invalid literal for int() with base 10: 'None'
ERROR 2020-09-30 13:07:32,315 log 30019 140181800482560 Internal Server Error: /api/check_resource/
Traceback (most recent call last):
  File "/home/cloudcopasi/cloud-copasi-new/ccEnv/lib64/python3.6/site-packages/django/core/handlers/exception.py", line 47, in inner
    response = get_response(request)
  File "/home/cloudcopasi/cloud-copasi-new/ccEnv/lib64/python3.6/site-packages/django/core/handlers/base.py", line 179, in _get_response
    response = wrapped_callback(request, *callback_args, **callback_kwargs)
  File "/home/cloudcopasi/cloud-copasi-new/ccEnv/lib64/python3.6/site-packages/django/views/generic/base.py", line 70, in view
    return self.dispatch(request, *args, **kwargs)
  File "/home/cloudcopasi/cloud-copasi-new/ccEnv/lib64/python3.6/site-packages/django/utils/decorators.py", line 43, in _wrapper
    return bound_method(*args, **kwargs)
  File "/home/cloudcopasi/cloud-copasi-new/ccEnv/lib64/python3.6/site-packages/django/views/decorators/csrf.py", line 54, in wrapped_view
    return view_func(*args, **kwargs)
  File "/home/cloudcopasi/cloud-copasi-new/cloud_copasi/web_interface/client_api/api_views.py", line 42, in dispatch
    return super(APIView, self).dispatch(request, *args, **kwargs)
  File "/home/cloudcopasi/cloud-copasi-new/ccEnv/lib64/python3.6/site-packages/django/views/generic/base.py", line 98, in dispatch
    return handler(request, *args, **kwargs)
  File "/home/cloudcopasi/cloud-copasi-new/cloud_copasi/web_interface/client_api/api_views.py", line 340, in get
    user_id = int(request.GET['user_id'])
ValueError: invalid literal for int() with base 10: 'None'
ERROR 2020-09-30 13:07:33,994 log 30019 140181800482560 Internal Server Error: /api/check_resource/
Traceback (most recent call last):
  File "/home/cloudcopasi/cloud-copasi-new/ccEnv/lib64/python3.6/site-packages/django/core/handlers/exception.py", line 47, in inner
    response = get_response(request)
  File "/home/cloudcopasi/cloud-copasi-new/ccEnv/lib64/python3.6/site-packages/django/core/handlers/base.py", line 179, in _get_response
    response = wrapped_callback(request, *callback_args, **callback_kwargs)
  File "/home/cloudcopasi/cloud-copasi-new/ccEnv/lib64/python3.6/site-packages/django/views/generic/base.py", line 70, in view
    return self.dispatch(request, *args, **kwargs)
  File "/home/cloudcopasi/cloud-copasi-new/ccEnv/lib64/python3.6/site-packages/django/utils/decorators.py", line 43, in _wrapper
    return bound_method(*args, **kwargs)
  File "/home/cloudcopasi/cloud-copasi-new/ccEnv/lib64/python3.6/site-packages/django/views/decorators/csrf.py", line 54, in wrapped_view
    return view_func(*args, **kwargs)
  File "/home/cloudcopasi/cloud-copasi-new/cloud_copasi/web_interface/client_api/api_views.py", line 42, in dispatch
    return super(APIView, self).dispatch(request, *args, **kwargs)
  File "/home/cloudcopasi/cloud-copasi-new/ccEnv/lib64/python3.6/site-packages/django/views/generic/base.py", line 98, in dispatch
    return handler(request, *args, **kwargs)
  File "/home/cloudcopasi/cloud-copasi-new/cloud_copasi/web_interface/client_api/api_views.py", line 340, in get
    user_id = int(request.GET['user_id'])
ValueError: invalid literal for int() with base 10: 'None'
